Workbook

Sheet Sezioni
A1: codice | B1: nominativo | C1: regione | D1: provincia | E1: anno di fondazione | F1: iscritti | G1: sitoweb | H1: email | I1: telefono | J1: PIVA | K1: CF | L1: PEC | M1: indirizzo Sede Legale | N1: Presidente | O1: Componenti | P1: Ente del Terzo Settore | Q1: Organo Di Controllo | R1: Sezione ref. tappa SICAI | S1: Sez. referente regionale
A2: 9299999 | B2: SEZ. PROVA | D2: MI | E2: 1950 | G2: www.sezioneprova.it | H2: sezprova@cai.it | I2: 123456 | L2: sezprova@cai.it | M2: Via Errico Petrella 19, 20124 Milano (MI) | N2: Presidente Sezprova | O2: [{"ruolo": "Delegato Elettivo", "nome": "Francesco", "cognome": "Amendola"}, {"ruolo": "Delegato Elettivo", "nome": "Fabrizio", "cognome": "Savini"}, {"ruolo": "Delegato Elettivo", "nome": "Caio", "cognome": "Sempronio"}, {"ruolo": "Presidente di Sezione", "nome": "Presidente", "cognome": "Sezprova"}]
A3: 9234026 | B3: SEZ. ARSITA | C3: ABRUZZO | D3: TE | E3: 2017 | F3: 204 | H3: arsita@cai.it | I3: 3281182237 | L3: arsita@pec.cai.it | M3: Via San Francesco snc, 64031 Arsita (TE) | N3: Manolo Pierannunzio | O3: [{"ruolo": "Revisore dei conti", "nome": "Catiuscia", "cognome": "Cacciatore"}, {"ruolo": "Consigliere", "nome": "Maria", "cognome": "Scocchia"}, {"ruolo": "Presidente di Sezione", "nome": "Manolo", "cognome": "Pierannunzio"}, {"ruolo": "Consigliere", "nome": "Tony", "cognome": "Orsetti"}, {"ruolo": "Vicepresidente", "nome": "Sandro", "cognome": "Cardone"}]
A4: 9234011 | B4: SEZ. ATESSA | C4: ABRUZZO | D4: CH | E4: 1978 | F4: 197 | G4: organizzazione.cai.it/sez-atessa/ | H4: atessa@cai.it | I4: .3332733526 | L4: atessa@pec.cai.it | M4: Loc. Vallaspra 2, 66041 ATESSA (CH) | N4: Concezio Grappasonno | O4: [{"ruolo": "Segretario", "nome": "Franca", "cognome": "Pasquarelli"}, {"ruolo": "Consigliere", "nome": "Giuseppina", "cognome": "Zaccardi"}, {"ruolo": "Consigliere", "nome": "Ida", "cognome": "D'Alonzo"}, {"ruolo": "Presidente di Sezione", "nome": "Concezio", "cognome": "Grappasonno"}, {"ruolo": "Tesoriere", "nome": "Katiuscia", "cognome": "Cinalli"}, {"ruolo": "Consigliere", "nome": "Maria", "cognome": "De Francesco"}, {"ruolo": "Revisore dei conti", "nome": "Mario", "cognome": "Tinaro"}, {"ruolo": "Vicepresidente", "nome": "Francesca", "cognome": "Tinaro"}]
A5: 9234013 | B5: SEZ. AVEZZANO | C5: ABRUZZO | D5: AQ | E5: 1980 | F5: 383 | G5: https://caiavezzano.it/ | H5: avezzano@cai.it | I5: 3388485199 | K5: 90008240666 | L5: avezzano@pec.cai.it | M5: Via Genserico Fontana 8, 67051 AVEZZANO (AQ) | N5: Antonio Massimiani | O5: [{"ruolo": "Presidente di Sezione", "nome": "Antonio", "cognome": "Massimiani"}, {"ruolo": "Tesoriere", "nome": "Antonio", "cognome": "Massimiani"}, {"ruolo": "Vicepresidente", "nome": "Costanzo", "cognome": "Villa"}, {"ruolo": "Consigliere", "nome": "Enio", "cognome": "Di Lorenzo"}, {"ruolo": "Segretario", "nome": "Gerardo", "cognome": "De Santis"}, {"ruolo": "Consigliere", "nome": "Giacomo", "cognome": "Continenza"}, {"ruolo": "Consigliere", "nome": "Angelo", "cognome": "Cipolloni"}, {"ruolo": "Consigliere", "nome": "Massimo", "cognome": "Gentile"}, {"ruolo": "Consigliere", "nome": "Valeria", "cognome": "Fiocchetti"}, {"ruolo": "Consigliere", "nome": "Walter", "cognome": "Silvestri"}]
A6: 9234024 | B6: SEZ. CARSOLI | C6: ABRUZZO | D6: AQ | E6: 2005 | F6: 234 | H6: carsoli@cai.it | I6: 1 | L6: carsoli@pec.cai.it | M6: Via Mario Galli casella postale 19 snc, 67061 CARSOLI (AQ) | N6: Giampiero Giuliani | O6: [{"ruolo": "Segretario", "nome": "Armando", "cognome": "Felli"}, {"ruolo": "Presidente di Sezione", "nome": "Giampiero", "cognome": "Giuliani"}, {"ruolo": "Consigliere", "nome": "Lorenzo", "cognome": "Augi"}, {"ruolo": "Consigliere", "nome": "Marco", "cognome": "Schiona"}]
A7: 9234015 | B7: SEZ. CASTEL DI SANGRO | C7: ABRUZZO | D7: AQ | E7: 1985 | F7: 177 | G7: organizzazione.cai.it/sez-castel-di-sangro/ | H7: casteldisangro@cai.it | I7: 333-7544405 | K7: 91001930667 | L7: casteldisangro@pec.cai.it | M7: Via del Leone 20, 67031 CASTEL DI SANGRO (AQ) | N7: Franco D'Ambrosio | O7: [{"ruolo": "Presidente di Sezione", "nome": "Franco", "cognome": "D'Ambrosio"}, {"ruolo": "Segretario", "nome": "Giovanni", "cognome": "Torrini"}]
A8: 9234010 | B8: SEZ. CASTELLI | C8: ABRUZZO | D8: TE | E8: 1976 | F8: 103 | G8: organizzazione.cai.it/sez-castelli/ | H8: castelli@cai.it | I8: 3391419402 | K8: 80010070672 | L8: castelli@pec.cai.it | M8: Via Convento 2, 64041 CASTELLI (TE) | N8: Giancarlo Di Pietro | O8: [{"ruolo": "Presidente di Sezione", "nome": "Giancarlo", "cognome": "Di Pietro"}]
A9: 9234001 | B9: SEZ. CHIETI | C9: ABRUZZO | D9: CH | E9: 1872 | F9: 306 | H9: segreteria@caichieti.it | I9: 3494401456 | J9: 00629300690 | K9: 80003750694 | L9: chieti@pec.cai.it | M9: Piazza dei Templi Romani 3, 66100 CHIETI (CH) | N9: Marco Grilli | O9: [{"ruolo": "Consigliere", "nome": "Alessio", "cognome": "Susi"}, {"ruolo": "Delegato Elettivo", "nome": "Igor", "cognome": "Arkhypenko"}, {"ruolo": "Vicepresidente", "nome": "Marcello", "cognome": "Borrone"}, {"ruolo": "Consigliere", "nome": "Gianni", "cognome": "Dal Buono"}, {"ruolo": "Consigliere", "nome": "Davide", "cognome": "Bonelli"}, {"ruolo": "Segretario", "nome": "Giovanni", "cognome": "D'Amico"}, {"ruolo": "Consigliere", "nome": "Francesco", "cognome": "Bonomo"}, {"ruolo": "Revisore dei conti", "nome": "Gianluca", "cognome": "Del Conte"}, {"ruolo": "Consigliere", "nome": "Giorgio", "cognome": "Micoli"}, {"ruolo": "Consigliere", "nome": "Claudia", "cognome": "Marrone"}, {"ruolo": "Presidente di Sezione", "nome": "Marco", "cognome": "Grilli"}, {"ruolo": "Tesoriere", "nome": "Pietro Luigi", "cognome": "Marino"}] | P9: ETS | Q9: No
A10: 9234012 | B10: SEZ. FARA S.MARTINO | C10: ABRUZZO | D10: CH | E10: 1980 | F10: 229 | H10: farasanmartino@cai.it | I10: 3207269364 | J10: 90016790694 | L10: farasanmartino@pec.cai.it | M10: Via Giuseppe Mazzini sn, 66015 FARA SAN MARTINO (CH) | N10: Giovanni Madonna | O10: [{"ruolo": "Revisore dei conti", "nome": "Adamo", "cognome": "D'Achille"}, {"ruolo": "Revisore dei conti", "nome": "Alessandro", "cognome": "Campitelli"}, {"ruolo": "Vicepresidente", "nome": "Antonio", "cognome": "Di Mito"}, {"ruolo": "Presidente di Sezione", "nome": "Giovanni", "cognome": "Madonna"}, {"ruolo": "Consigliere", "nome": "Sergio", "cognome": "Di Giuseppe"}, {"ruolo": "Consigliere", "nome": "Silverio", "cognome": "Di Lello"}, {"ruolo": "Consigliere", "nome": "Mauro", "cognome": "Giancristofaro"}, {"ruolo": "Segretario", "nome": "Gianpaolo", "cognome": "Ricciuti"}, {"ruolo": "Consigliere", "nome": "Pietro", "cognome": "Maesa"}, {"ruolo": "Vicepresidente", "nome": "Francesco", "cognome": "Masciantonio"}, {"ruolo": "Consigliere", "nome": "Michele", "cognome": "D'Orazio"}, {"ruolo": "Consigliere", "nome": "Rita", "cognome": "Amato"}, {"ruolo": "Tesoriere", "nome": "Sante", "cognome": "Liberatoscioli"}]
A11: 9234008 | B11: SEZ. FARINDOLA | C11: ABRUZZO | D11: PE | E11: 1974 | F11: 101 | G11: www.caifarindola.it | H11: farindola@cai.it | I11: 0 | K11: 80019430687 | L11: farindola@pec.cai.it | M11: Via San Rocco 8, 65010 FARINDOLA (PE) | O11: []
A12: 9234007 | B12: SEZ. GUARDIAGRELE | C12: ABRUZZO | D12: CH | E12: 1953 | F12: 269 | H12: guardiagrele@cai.it | K12: 80000600694 | L12: guardiagrele@pec.cai.it | M12: ROMA C/O IACOVELLA CARLO 97, 66016 GUARDIAGRELE (CH) | N12: Antonio Taraborrelli | O12: [{"ruolo": "Delegato Elettivo", "nome": "Pierluigi", "cognome": "Di Prinzio"}, {"ruolo": "Presidente di Sezione", "nome": "Antonio", "cognome": "Taraborrelli"}]
A13: 9234018 | B13: SEZ. ISOLA DEL GRAN SASSO | C13: ABRUZZO | D13: TE | E13: 1987 | F13: 227 | G13: www.caiisola.it | H13: isoladelgransasso@cai.it | I13: 3488577052 | K13: 92008430677 | L13: isoladelgransasso@pec.cai.it | M13: Largo del Torrione 8, 64045 Isola del Gran Sasso d'Italia (TE) | N13: Francesco Trifoni | O13: [{"ruolo": "Consigliere", "nome": "Enza", "cognome": "Lombardi"}, {"ruolo": "Presidente di Sezione", "nome": "Francesco", "cognome": "Trifoni"}, {"ruolo": "Consigliere", "nome": "Marco", "cognome": "Carlini"}, {"ruolo": "Revisore dei conti", "nome": "Christian", "cognome": "Menei"}, {"ruolo": "Consigliere", "nome": "Luca", "cognome": "Morrone"}, {"ruolo": "Revisore dei conti", "nome": "Patrizio", "cognome": "Pallotta"}, {"ruolo": "Revisore dei conti", "nome": "Umberto", "cognome": "Cerquone"}]
A14: 9234002 | B14: SEZ. L'AQUILA | C14: ABRUZZO | D14: AQ | E14: 1874 | F14: 908 | G14: https://cailaquila.it/ | H14: laquila@cai.it | I14: 0862028225 | J14: 00145680666 | K14: 00145680666 | L14: laquila@pec.cai.it | M14: Via Sassa 34, 67100 L'AQUILA (AQ) | N14: Ugo Marinucci | O14: [{"ruolo": "Delegato Elettivo", "nome": "Felice", "cognome": "Flati"}, {"ruolo": "Segretario", "nome": "Francesca", "cognome": "Larocchia"}, {"ruolo": "Segretario", "nome": "Francesca", "cognome": "Larocchia"}, {"ruolo": "Consigliere", "nome": "Giulia", "cognome": "Scaglietta"}, {"ruolo": "Responsabile di segreteria", "nome": "Giulia", "cognome": "Scaglietta"}, {"ruolo": "Responsabile di segreteria", "nome": "Leonardo", "cognome": "Esposito"}, {"ruolo": "Tesoriere", "nome": "Leonardo", "cognome": "Esposito"}, {"ruolo": "Consigliere", "nome": "Corrado", "cognome": "Marsili"}, {"ruolo": "Delegato Elettivo", "nome": "Monica", "cognome": "Maurizio"}, {"ruolo": "Consigliere", "nome": "Gian Luca", "cognome": "Ricciardulli"}, {"ruolo": "Presidente di Sezione", "nome": "Ugo", "cognome": "Marinucci"}, {"ruolo": "Consigliere", "nome": "Valeria", "cognome": "Vizioli"}] | P14: APS - ETS | Q14: No
A15: 9234017 | B15: SEZ. LANCIANO | C15: ABRUZZO | D15: CH | E15: 1986 | F15: 275 | G15: cailanciano.it | H15: lanciano@cai.it | I15: 3271078241 | J15: 90008320690 | K15: 90008320690 | L15: lanciano@pec.cai.it | M15: VIA DEI FRENTANI 43, 66034 LANCIANO (CH) | N15: Catia Manfre' | O15: [{"ruolo": "Responsabile di segreteria", "nome": "Alessandro", "cognome": "Tenaglia"}, {"ruolo": "Revisore dei conti", "nome": "Assunta", "cognome": "Colacioppo"}, {"ruolo": "Presidente di Sezione", "nome": "Catia", "cognome": "Manfre'"}, {"ruolo": "Revisore dei conti", "nome": "Antonio", "cognome": "Scacciavillani"}, {"ruolo": "Consigliere", "nome": "Antonio", "cognome": "Francia"}, {"ruolo": "Segretario", "nome": "Giovanni", "cognome": "Giancristofaro"}, {"ruolo": "Revisore dei conti", "nome": "Gianluca", "cognome": "Iurisci"}, {"ruolo": "Tesoriere", "nome": "Marcella", "cognome": "Simongini"}, {"ruolo": "Delegato Elettivo", "nome": "Martina Ines", "cognome": "Melizzi"}, {"ruolo": "Consigliere", "nome": "Nicola", "cognome": "Luongo"}, {"ruolo": "Tesoriere", "nome": "Pier Franco", "cognome": "Ferrara"}, {"ruolo": "Vicepresidente", "nome": "Fabio", "cognome": "Sireni"}] | P15: APS - ETS | Q15: No
A16: 9234023 | B16: SEZ. LORETO APRUTINO | C16: ABRUZZO | D16: PE | E16: 2006 | F16: 108 | G16: www.cailoretoaprutino.it | H16: loretoaprutino@cai.it | I16: 345 9359339 | J16: 01831370687 | K16: 01831370687 | L16: loretoaprutino@pec.cai.it | M16: Via delle Monache 1, 65014 LORETO APRUTINO (PE) | N16: Arturo Acciavatti | O16: [{"ruolo": "Consigliere", "nome": "Andrea", "cognome": "Acciavatti"}, {"ruolo": "Consigliere", "nome": "Antonietta", "cognome": "Di Girolamo"}, {"ruolo": "Presidente di Sezione", "nome": "Arturo", "cognome": "Acciavatti"}, {"ruolo": "Segretario", "nome": "Daniele", "cognome": "Berardi"}, {"ruolo": "Tesoriere", "nome": "Caterina", "cognome": "Ferri"}, {"ruolo": "Consigliere", "nome": "Daniela", "cognome": "Candeloro"}, {"ruolo": "Consigliere", "nome": "Emanuele", "cognome": "Evangelista"}, {"ruolo": "Consigliere", "nome": "Fabio", "cognome": "Chiappini"}, {"ruolo": "Vicepresidente", "nome": "Fabio", "cognome": "Pellegrini"}]
A17: 9234020 | B17: SEZ. ORTONA | C17: ABRUZZO | D17: CH | E17: 1991 | F17: 146 | G17: organizzazione.cai.it/sez-ortona | H17: ortona@cai.it | I17: 0 | K17: 91002490695 | L17: ortona@pec.cai.it | M17: Via Civiltà del Lavoro angolo Viale Margherita d’Austria, 66026 ORTONA (CH) | N17: Angelo Radoccia | O17: [{"ruolo": "Presidente di Sezione", "nome": "Angelo", "cognome": "Radoccia"}]
A18: 9234006 | B18: SEZ. PENNE | C18: ABRUZZO | D18: PE | E18: 1950 | F18: 212 | G18: caipenne.it | H18: penne@cai.it | I18: +393396207568 | K18: 80014770681 | L18: penne@pec.cai.it | M18: Piazza XX Settembre 10, 65017 PENNE (PE) | N18: Cinzia Abruzzese | O18: [{"ruolo": "Consigliere", "nome": "Antonio", "cognome": "Girasole"}, {"ruolo": "Presidente di Sezione", "nome": "Cinzia", "cognome": "Abruzzese"}, {"ruolo": "Revisore dei conti", "nome": "Diana", "cognome": "Di Simone"}, {"ruolo": "Consigliere", "nome": "Francesca", "cognome": "D'Alberto"}, {"ruolo": "Revisore dei conti", "nome": "Roberto", "cognome": "Giancaterino"}, {"ruolo": "Consigliere", "nome": "Gianluca", "cognome": "D'Andrea"}, {"ruolo": "Segretario", "nome": "Gianluca", "cognome": "D'Andrea"}, {"ruolo": "Vicepresidente", "nome": "Laura", "cognome": "Delli Castelli"}, {"ruolo": "Consigliere", "nome": "Luciano", "cognome": "Schiazza"}, {"ruolo": "Consigliere", "nome": "Milo", "cognome": "Sabatini"}, {"ruolo": "Revisore dei conti", "nome": "Sandro", "cognome": "Rossi"}, {"ruolo": "Consigliere", "nome": "Silvio Sergio", "cognome": "Fortunato"}]
A19: 9234005 | B19: SEZ. PESCARA | C19: ABRUZZO | D19: PE | E19: 1932 | F19: 346 | H19: pescara@cai.it | I19: 085.54621 | J19: 01823940687 | K19: 91041720680 | L19: pescara@pec.cai.it | M19: Via Aldo Moro 15/8, 65129 PESCARA (PE) | N19: Alessandro Galli | O19: [{"ruolo": "Presidente di Sezione", "nome": "Alessandro", "cognome": "Galli"}, {"ruolo": "Delegato Elettivo", "nome": "Elvio", "cognome": "Verna"}]
A20: 9234016 | B20: SEZ. POPOLI | C20: ABRUZZO | D20: PE | E20: 1985 | F20: 190 | H20: popoli@cai.it | I20: 08598599 | L20: popoli@pec.cai.it | M20: Via Guglielmo Marconi c/o Carlo Diodati - Casella Postale 8 20, 65026 POPOLI (PE) | N20: Claudio Di Gregorio | O20: [{"ruolo": "Consigliere", "nome": "Camillo", "cognome": "Di Loreto"}, {"ruolo": "Vicepresidente", "nome": "Carlo", "cognome": "Diodati"}, {"ruolo": "Consigliere", "nome": "Cristina", "cognome": "Salvatore"}, {"ruolo": "Consigliere", "nome": "Davide", "cognome": "Piccioli"}, {"ruolo": "Segretario", "nome": "Donato", "cognome": "Di Benedetto"}, {"ruolo": "Tesoriere", "nome": "Biagio", "cognome": "Di Francescantonio"}, {"ruolo": "Consigliere", "nome": "Venanzio", "cognome": "Golini"}, {"ruolo": "Consigliere", "nome": "Luca", "cognome": "Mariani"}, {"ruolo": "Presidente di Sezione", "nome": "Claudio", "cognome": "Di Gregorio"}] | R20: Sì
A21: 9234004 | B21: SEZ. SULMONA | C21: ABRUZZO | D21: AQ | E21: 1952 | F21: 305 | H21: sulmona@cai.it | I21: 3313742409 | L21: caisulmona@pec.it | M21: GIUSEPPE ANDREA ANGELONI C/OCOMUNITA'MONTANAPELIGNA 11, 67039 SULMONA (AQ) | N21: Nino Restaino | O21: [{"ruolo": "Revisore dei conti", "nome": "Adriano", "cognome": "Marcantonio"}, {"ruolo": "Delegato Elettivo", "nome": "Domenico", "cognome": "Capaldo"}, {"ruolo": "Vicepresidente", "nome": "Domenico", "cognome": "Capaldo"}, {"ruolo": "Tesoriere", "nome": "Giovanni", "cognome": "Tarquini"}, {"ruolo": "Consigliere", "nome": "Maria Pia", "cognome": "Lamberti"}, {"ruolo": "Consigliere", "nome": "Massimo", "cognome": "Mariani"}, {"ruolo": "Presidente di Sezione", "nome": "Nino", "cognome": "Restaino"}, {"ruolo": "Segretario", "nome": "Roberto", "cognome": "Bezzu"}, {"ruolo": "Revisore dei conti", "nome": "Simonetta", "cognome": "Cipriani"}, {"ruolo": "Revisore dei conti", "nome": "Tonino", "cognome": "Proietto"}, {"ruolo": "Consigliere", "nome": "Valter", "cognome": "Adeante"}] | R21: Sì | S21: Sez. referente regionale
A22: 9234003 | B22: SEZ. TERAMO | C22: ABRUZZO | D22: TE | E22: 1914 | F22: 423 | G22: www.caiteramo.it | H22: teramo@cai.it | I22: 0 | J22: 00908080674 | K22: 80006280673 | L22: teramo@pec.cai.it | M22: Via Cona 180, 64100 TERAMO (TE) | N22: Giorgio D'Egidio | O22: [{"ruolo": "Presidente di Sezione", "nome": "Giorgio", "cognome": "D'Egidio"}, {"ruolo": "Vicepresidente", "nome": "Lia", "cognome": "Sisino"}, {"ruolo": "Segretario", "nome": "Mauro", "cognome": "Di Dionisio"}] | P22: Avviata procedura di iscrizione | R22: Sì
A23: 9234027 | B23: SEZ. VAL VIBRATA (MONTI GEMELLI) | C23: ABRUZZO | D23: TE | E23: 2021 | F23: 380 | H23: valvibrata@cai.it | I23: . | L23: valvibrata@pec.cai.it | M23: Via del Lavoro c/o Palestra arrampicata Blue Rock (Centro Sportivo IRIDE) 14, 64014 Martinsicuro (TE) | N23: Davide Francioni | O23: [{"ruolo": "Presidente di Sezione", "nome": "Davide", "cognome": "Francioni"}] | P23: APS - ETS | Q23: No
A24: 9234019 | B24: SEZ. VALLE ROVETO | C24: ABRUZZO | D24: AQ | E24: 1988 | F24: 142 | H24: valleroveto@cai.it | I24: 0863.978152 | K24: 90019100669 | L24: valleroveto@pec.cai.it | M24: Via Ripandelli ex asilo "Città di Genova" snc, 67054 CIVITELLA ROVETO (AQ) | N24: Raffaele Allegritti | O24: [{"ruolo": "Vicepresidente", "nome": "Lucia", "cognome": "Mastropietro"}, {"ruolo": "Consigliere", "nome": "Nicholas", "cognome": "Novelli"}, {"ruolo": "Presidente di Sezione", "nome": "Raffaele", "cognome": "Allegritti"}]
A25: 9234025 | B25: SEZ. VALLELONGA - COPPO DELL'ORSO | C25: ABRUZZO | D25: AQ | E25: 2015 | F25: 150 | G25: Www.coppodellorso.it | H25: coppodellorso@cai.it | I25: 3462473725 | J25: 01797560669 | K25: 9002320662 | L25: vallelonga-coppodellorso@pec.cai.it | M25: Via Garibaldi 1, 67059 Trasacco (AQ) | N25: Odorisio Boccia | O25: [{"ruolo": "Presidente di Sezione", "nome": "Odorisio", "cognome": "Boccia"}] | R25: Sì
A26: 9234022 | B26: SEZ. VASTO | C26: ABRUZZO | D26: CH | E26: 1999 | F26: 273 | G26: wwww.caivasto.it | H26: vasto@cai.it | I26: 3515539370 | K26: 92013420697 | L26: vasto@pec.cai.it | M26: Via delle Cisterne 4, 66054 VASTO (CH) | N26: Francesco Famiani | O26: [{"ruolo": "Presidente di Sezione", "nome": "Francesco", "cognome": "Famiani"}, {"ruolo": "Delegato Elettivo", "nome": "Giuseppe", "cognome": "Celenza"}] | R26: Sì
A27: 9242002 | B27: SEZ. LAGONEGRO | C27: BASILICATA | D27: PZ | E27: 1995 | F27: 202 | G27: www.cailagonegro.com | H27: lagonegro@cai.it | I27: 3481701973 (presidente) | J27: 02143370761 | K27: 91001120764 | L27: lagonegro@pec.cai.it | M27: Viale Roma 9, 85042 LAGONEGRO (PZ) | N27: Pompeo Limongi | O27: [{"ruolo": "Revisore dei conti", "nome": "Antonio", "cognome": "Spaltro"}, {"ruolo": "Delegato Elettivo", "nome": "Graziella", "cognome": "D'Agostino"}, {"ruolo": "Tesoriere", "nome": "Giuseppe", "cognome": "Truncellito"}, {"ruolo": "Consigliere", "nome": "Giuseppe", "cognome": "Truncellito"}, {"ruolo": "Delegato Elettivo", "nome": "Lucia", "cognome": "Mancusi"}, {"ruolo": "Delegato Elettivo", "nome": "Marianna", "cognome": "Ferraro"}, {"ruolo": "Revisore dei conti", "nome": "Marianna", "cognome": "Ferraro"}, {"ruolo": "Revisore dei conti", "nome": "Bruno", "cognome": "Niola"}, {"ruolo": "Presidente di Sezione", "nome": "Pompeo", "cognome": "Limongi"}, {"ruolo": "Consigliere", "nome": "Salvatore", "cognome": "Ledonne"}, {"ruolo": "Consigliere", "nome": "Silvia", "cognome": "Di Taranto"}, {"ruolo": "Consigliere", "nome": "Vincenzo Daniele", "cognome": "Gulfo"}, {"ruolo": "Vicepresidente", "nome": "Vincenzo Daniele", "cognome": "Gulfo"}] | P27: Avviata procedura di iscrizione | R27: Sì
A28: 9242004 | B28: SEZ. MATERA | C28: BASILICATA | D28: MT | E28: 2021 | F28: 279 | G28: www.caimatera.it | H28: matera@cai.it | I28: 3351673705 | L28: matera@pec.cai.it | M28: Via della Croce 1, 75100 Matera (MT) | N28: Margherita Sirritiello | O28: [{"ruolo": "Delegato Elettivo", "nome": "Alessandro", "cognome": "Petrigliano"}, {"ruolo": "Delegato Elettivo", "nome": "Antonio", "cognome": "Chietera"}, {"ruolo": "Revisore dei conti", "nome": "Raffaele", "cognome": "Capoccello"}, {"ruolo": "Consigliere", "nome": "Giacinta", "cognome": "Moliterni"}, {"ruolo": "Delegato Elettivo", "nome": "Elio", "cognome": "Di Bari"}, {"ruolo": "Delegato Elettivo", "nome": "Cosimo", "cognome": "Buono"}, {"ruolo": "Consigliere", "nome": "Felice", "cognome": "Santantonio"}, {"ruolo": "Delegato Elettivo", "nome": "Francesco Paolo", "cognome": "Oliva"}, {"ruolo": "Consigliere", "nome": "Gianfranco", "cognome": "Scalcione"}, {"ruolo": "Consigliere", "nome": "Giulia", "cognome": "Coretti"}, {"ruolo": "Revisore dei conti", "nome": "Luigi", "cognome": "Lanzillotta"}, {"ruolo": "Revisore dei conti", "nome": "Maria Rosaria", "cognome": "Padula"}, {"ruolo": "Consigliere", "nome": "Michele", "cognome": "Colonna"}, {"ruolo": "Presidente di Sezione", "nome": "Margherita", "cognome": "Sirritiello"}, {"ruolo": "Delegato Elettivo", "nome": "Paolo Pancrazio", "cognome": "Baldassarre"}, {"ruolo": "Consigliere", "nome": "Pierfrancesco", "cognome": "Matarazzo"}, {"ruolo": "Consigliere", "nome": "Simona", "cognome": "Di Tomaso"}, {"ruolo": "Consigliere", "nome": "Antonio Vincenzo", "cognome": "Alba"}] | P28: APS - ETS | Q28: No
A29: 9242003 | B29: SEZ. MELFI | C29: BASILICATA | D29: PZ | E29: 2015 | F29: 146 | G29: organizzazione.cai.it/sez-melfi | H29: melfi@cai.it | I29: 3333746453 | L29: melfi@pec.cai.it | M29: Via G. D’Annunzio c/o Autoparking 35, 85025 Melfi (PZ) | N29: Monica Pocchiari | O29: [{"ruolo": "Consigliere", "nome": "Angelo", "cognome": "Bocca"}, {"ruolo": "Tesoriere", "nome": "Adele", "cognome": "Amoroso"}, {"ruolo": "Revisore dei conti", "nome": "Alfredo", "cognome": "Sonnessa"}, {"ruolo": "Delegato Elettivo", "nome": "Pasqualina", "cognome": "Vucci"}, {"ruolo": "Consigliere", "nome": "Monica", "cognome": "Asquino"}, {"ruolo": "Consigliere", "nome": "Carmen", "cognome": "De Angelis"}, {"ruolo": "Segretario", "nome": "Clelia", "cognome": "Carnevale"}, {"ruolo": "Vicepresidente", "nome": "Lucrezia", "cognome": "Croce"}, {"ruolo": "Consigliere", "nome": "Daniele", "cognome": "Simonetti"}, {"ruolo": "Consigliere", "nome": "Marianna", "cognome": "Cefola"}, {"ruolo": "Consigliere", "nome": "Michele", "cognome": "Placido"}, {"ruolo": "Revisore dei conti", "nome": "Michele", "cognome": "Cennamo"}, {"ruolo": "Delegato Elettivo", "nome": "Michelarcangelo", "cognome": "Moscaritolo"}, {"ruolo": "Presidente di Sezione", "nome": "Monica", "cognome": "Pocchiari"}, {"ruolo": "Revisore dei conti", "nome": "Valentina", "cognome": "Loconsolo"}] | P29: ODV - ETS | Q29: No | R29: Sì
A30: 9242001 | B30: SEZ. POTENZA | C30: BASILICATA | D30: PZ | E30: 1990 | F30: 301 | G30: organizzazione.cai.it/sez-potenza | H30: potenza@cai.it | I30: 320 1890881 (Rifugio) | K30: 96031200767 | L30: potenza@pec.cai.it | M30: Via Tirreno Fabbricato A Del Favero, 85100 POTENZA (PZ) | N30: Antonio Aicale | O30: [{"ruolo": "Presidente di Sezione", "nome": "Antonio", "cognome": "Aicale"}, {"ruolo": "Responsabile di segreteria", "nome": "Amedeo", "cognome": "Tucci"}, {"ruolo": "Consigliere", "nome": "Amedeo", "cognome": "Tucci"}, {"ruolo": "Consigliere", "nome": "Angela", "cognome": "Cocuzzo"}, {"ruolo": "Delegato Elettivo", "nome": "Anna", "cognome": "Taurisano"}, {"ruolo": "Delegato Elettivo", "nome": "Carmela", "cognome": "Romaniello"}, {"ruolo": "Revisore dei conti", "nome": "Donatella", "cognome": "Romaniello"}, {"ruolo": "Revisore dei conti", "nome": "Gaetano", "cognome": "Liccione"}, {"ruolo": "Consigliere", "nome": "Giuseppina", "cognome": "Dolce"}, {"ruolo": "Revisore dei conti", "nome": "Livia", "cognome": "Carella"}, {"ruolo": "Segretario", "nome": "Pierluigi", "cognome": "Casella"}, {"ruolo": "Delegato Elettivo", "nome": "Pierluigi", "cognome": "Casella"}, {"ruolo": "Delegato Elettivo", "nome": "Rosalena", "cognome": "Cembrola"}, {"ruolo": "Vicepresidente", "nome": "Franca", "cognome": "Di Trana"}, {"ruolo": "Consigliere", "nome": "Nicola", "cognome": "Pugliese"}, {"ruolo": "Delegato Elettivo", "nome": "Vincenzo", "cognome": "De Palma"}, {"ruolo": "Delegato Elettivo", "nome": "Vito Antonio", "cognome": "Mancusi"}, {"ruolo": "Tesoriere", "nome": "Vito Antonio", "cognome": "Mancusi"}] | P30: ODV - ETS | Q30: No
A31: 9244005 | B31: SEZ. CASTROVILLARI | C31: CALABRIA | D31: CS | E31: 1999 | F31: 348 | G31: www.caicastrovillari.it | H31: castrovillari@cai.it | I31: 334.1005054 | J31: 02934200789 | K31: 94005130789 | L31: castrovillari@pec.cai.it | M31: VIA CAIROLI 80, 87012 CASTROVILLARI (CS) | N31: Carla Primavera | O31: [{"ruolo": "Consigliere", "nome": "Luigi", "cognome": "Arcovio"}, {"ruolo": "Responsabile di segreteria", "nome": "Gaetano", "cognome": "Cersosimo"}, {"ruolo": "Vicepresidente", "nome": "Gaetano", "cognome": "Cersosimo"}, {"ruolo": "Presidente di Sezione", "nome": "Carla", "cognome": "Primavera"}, {"ruolo": "Tesoriere", "nome": "Eugenio Antonio", "cognome": "Iannelli"}, {"ruolo": "Consigliere", "nome": "Luana", "cognome": "Macrini"}, {"ruolo": "Delegato Elettivo", "nome": "Mariarosaria", "cognome": "D'Atri"}, {"ruolo": "Consigliere", "nome": "Paolo", "cognome": "Viceconte"}, {"ruolo": "Revisore dei conti", "nome": "Graziella", "cognome": "Romano"}, {"ruolo": "Revisore dei conti", "nome": "Rossella", "cognome": "Alois"}, {"ruolo": "Consigliere", "nome": "Gaetano", "cognome": "Sangineti"}] | P31: APS - ETS | Q31: No | R31: Sì
A32: 9244004 | B32: SEZ. CATANZARO | C32: CALABRIA | D32: CZ | E32: 1990 | F32: 248 | G32: organizzazione.cai.it/sez-catanzaro | H32: catanzaro@cai.it | I32: 3478051252 | K32: 97020360794 | L32: catanzaro@pec.cai.it | M32: Piazza Duomo 9, 88100 CATANZARO (CZ) | N32: Piergiorgio Iannaccaro | O32: [{"ruolo": "Delegato Elettivo", "nome": "Demetrio", "cognome": "Santone"}, {"ruolo": "Revisore dei conti", "nome": "Rosanna", "cognome": "Riccelli"}, {"ruolo": "Revisore dei conti", "nome": "Alessandro", "cognome": "Gaglianese"}, {"ruolo": "Responsabile di segreteria", "nome": "Marco", "cognome": "Garcea"}, {"ruolo": "Segretario", "nome": "Marco", "cognome": "Garcea"}, {"ruolo": "Presidente di Sezione", "nome": "Piergiorgio", "cognome": "Iannaccaro"}, {"ruolo": "Tesoriere", "nome": "Vitaliano", "cognome": "Oliverio"}] | P32: APS - ETS | Q32: No | R32: Sì
A33: 9244002 | B33: SEZ. COSENZA | C33: CALABRIA | D33: CS | E33: 1990 | F33: 240 | H33: cosenza@cai.it | I33: 098475204 | L33: cosenza@pec.cai.it | M33: Via Casali - Stazione FC, 87100 COSENZA (CS) | N33: Maria Talarico | O33: [{"ruolo": "Presidente di Sezione", "nome": "Maria", "cognome": "Talarico"}] | P33: APS - ETS | Q33: No | R33: Sì | S33: Sez. referente regionale
A34: 9244001 | B34: SEZ. REGGIO CALABRIA | C34: CALABRIA | D34: RC | E34: 1932 | F34: 286 | G34: organizzazione.cai.it/sez-reggio-calabria/ | H34: info@caireggio.it | I34: 0 | K34: 92006240805 | L34: reggiocalabria@pec.cai.it | M34: Via Sbarre Superiore 61/C, 89132 REGGIO CALABRIA (RC) | N34: Giandomenico Posillipo | O34: [{"ruolo": "Consigliere", "nome": "Carmelo", "cognome": "Idone"}, {"ruolo": "Presidente di Sezione", "nome": "Giandomenico", "cognome": "Posillipo"}, {"ruolo": "Segretario", "nome": "Marino", "cognome": "Mollo"}, {"ruolo": "Delegato Elettivo", "nome": "Pino", "cognome": "Perrone"}, {"ruolo": "Vicepresidente", "nome": "Pino", "cognome": "Perrone"}] | P34: APS - ETS | Q34: No | R34: Sì
A35: 9244006 | B35: SEZ. VERBICARO | C35: CALABRIA | D35: CS | E35: 2013 | F35: 146 | H35: caiverbicaro2014@gmail.com | I35: 3356590362 | K35: 96027600780 | L35: verbicaro@pec.cai.it | M35: Via Orologio c/o Centro Educazione Ambientale 11, 87020 VERBICARO (CS) | N35: Alberto Dito | O35: [{"ruolo": "Presidente di Sezione", "nome": "Alberto", "cognome": "Dito"}, {"ruolo": "Consigliere", "nome": "Ennio", "cognome": "Benvenuto"}, {"ruolo": "Vicepresidente", "nome": "Ennio", "cognome": "Benvenuto"}, {"ruolo": "Segretario", "nome": "Francesco", "cognome": "Quattrone"}, {"ruolo": "Segretario", "nome": "Francesco", "cognome": "Quattrone"}, {"ruolo": "Consigliere", "nome": "Carmine", "cognome": "Cirimele"}] | P35: APS - ETS | Q35: Sì
A36: 9238004 | B36: SEZ. AVELLINO | C36: CAMPANIA | D36: AV | E36: 1994 | F36: 325 | G36: www.caiavellino.it | H36: avellino@cai.it | I36: 3274022250 | L36: avellino@pec.cai.it | M36: AntonioTedeschi 18/f, 83100 Avellino (AV) | N36: Alfonso De Cesare | O36: [{"ruolo": "Presidente di Sezione", "nome": "Alfonso", "cognome": "De Cesare"}, {"ruolo": "Consigliere", "nome": "Francesca", "cognome": "Bellucci"}, {"ruolo": "Consigliere", "nome": "Gaetano", "cognome": "Izzo"}, {"ruolo": "Consigliere", "nome": "Giovanni", "cognome": "Rosato"}, {"ruolo": "Revisore dei conti", "nome": "Giulia", "cognome": "Affinito"}, {"ruolo": "Tesoriere", "nome": "Liliana", "cognome": "Cafasso"}, {"ruolo": "Delegato Elettivo", "nome": "Luca Gerardo Pio", "cognome": "Fiorillo"}, {"ruolo": "Consigliere", "nome": "Mario", "cognome": "Delli Priscoli"}, {"ruolo": "Vicepresidente", "nome": "Marco", "cognome": "Figliolia"}, {"ruolo": "Revisore dei conti", "nome": "Maria", "cognome": "Cristallo"}, {"ruolo": "Segretario", "nome": "Maria Agnese", "cognome": "Giordano"}, {"ruolo": "Consigliere", "nome": "Pietro Pio", "cognome": "Liquidato"}, {"ruolo": "Consigliere", "nome": "Roberto", "cognome": "Napolitano"}, {"ruolo": "Revisore dei conti", "nome": "Vito", "cognome": "Abate"}] | P36: APS - ETS | Q36: Sì
A37: 9238008 | B37: SEZ. BENEVENTO | C37: CAMPANIA | D37: BN | E37: 2007 | F37: 407 | H37: benevento@cai.it | I37: 3207406508 | K37: 92047030629 | L37: benevento@pec.cai.it | M37: Via Vitulanese 103, 82100 BENEVENTO (BN) | N37: Berardino Bocchino | O37: [{"ruolo": "Tesoriere", "nome": "Antonio", "cognome": "Giardiello"}, {"ruolo": "Consigliere", "nome": "Antonio", "cognome": "Giardiello"}, {"ruolo": "Presidente di Sezione", "nome": "Berardino", "cognome": "Bocchino"}, {"ruolo": "Revisore dei conti", "nome": "Daniele", "cognome": "Izzo"}, {"ruolo": "Delegato Elettivo", "nome": "Vincenzo", "cognome": "Auletta"}, {"ruolo": "Vicepresidente", "nome": "Vincenzo", "cognome": "Auletta"}, {"ruolo": "Consigliere", "nome": "Anna", "cognome": "Mazzeo"}, {"ruolo": "Consigliere", "nome": "Orazio", "cognome": "Nardone"}, {"ruolo": "Revisore dei conti", "nome": "Piera", "cognome": "Altieri"}, {"ruolo": "Segretario", "nome": "Rossana", "cognome": "D'Arienzo"}, {"ruolo": "Consigliere", "nome": "Rossana", "cognome": "D'Arienzo"}, {"ruolo": "Consigliere", "nome": "Vilma", "cognome": "Tarantino"}, {"ruolo": "Revisore dei conti", "nome": "Umberto", "cognome": "Ficociello"}] | P37: ETS | Q37: Sì
A38: 9238006 | B38: SEZ. CASERTA | C38: CAMPANIA | D38: CE | E38: 1998 | F38: 220 | G38: https://www.caicaserta.it | H38: caserta@cai.it | I38: 3333838602 | J38: 0 | K38: 93067720610 | L38: caserta@pec.cai.it | M38: senza indirizzo, 81100 CASERTA (CE) | N38: Giuseppe Salvatore Spina | O38: [{"ruolo": "Tesoriere", "nome": "Anna", "cognome": "De Lucia"}, {"ruolo": "Consigliere", "nome": "Davide", "cognome": "Bernieri"}, {"ruolo": "Consigliere", "nome": "Ciro", "cognome": "Bologna"}, {"ruolo": "Presidente di Sezione", "nome": "Giuseppe Salvatore", "cognome": "Spina"}, {"ruolo": "Consigliere", "nome": "Antonio", "cognome": "Santillo"}, {"ruolo": "Revisore dei conti", "nome": "Carmine", "cognome": "Venasco"}, {"ruolo": "Consigliere", "nome": "Mary Teresa", "cognome": "Gray"}, {"ruolo": "Revisore dei conti", "nome": "Paola", "cognome": "Formati"}, {"ruolo": "Consigliere", "nome": "Raffaele", "cognome": "Aguzzoli"}, {"ruolo": "Revisore dei conti", "nome": "Rosario", "cognome": "Brocchieri"}, {"ruolo": "Consigliere", "nome": "Terenzio", "cognome": "De Tommaso"}, {"ruolo": "Consigliere", "nome": "Vincenzo", "cognome": "Sollitto"}] | P38: APS - ETS | Q38: Sì
A39: 9238009 | B39: SEZ. CASTELLAMMARE DI STABIA | C39: CAMPANIA | D39: NA | E39: 2009 | F39: 313 | H39: castellammaredistabia@cai.it | L39: castellammaredistabia@pec.cai.it | M39: SAN VINCENZO C/O CPS 15, 80053 CASTELLAMMARE DI STABIA (NA) | N39: Raffaele Luise | O39: [{"ruolo": "Delegato Elettivo", "nome": "Agnese", "cognome": "Sicignano"}, {"ruolo": "Responsabile di segreteria", "nome": "Mariagrazia", "cognome": "De Meo"}, {"ruolo": "Presidente di Sezione", "nome": "Raffaele", "cognome": "Luise"}, {"ruolo": "Vicepresidente", "nome": "Riccardo", "cognome": "Ballo"}]
A40: 9238002 | B40: SEZ. CAVA DEI TIRRENI | C40: CAMPANIA | D40: SA | E40: 1939 | F40: 224 | H40: cavadeitirreni@cai.it | I40: 089 345186 | K40: 95058050659 | L40: cavadeitirreni@pec.cai.it | M40: Corso Mazzini 6, 84013 CAVA DE' TIRRENI (SA) | N40: Lucia Palumbo | O40: [{"ruolo": "Tesoriere", "nome": "Antonio", "cognome": "Mangini"}, {"ruolo": "Vicepresidente", "nome": "Giuseppe", "cognome": "Fortunato"}, {"ruolo": "Presidente di Sezione", "nome": "Lucia", "cognome": "Palumbo"}]
...

Sheet Sottosezioni
A1: codice | B1: nominativo | C1: sezione | D1: codice sezione | E1: regione | F1: provincia | G1: email | H1: indirizzo
A2: 9101002 | B2: GRUPPO CENTRALE C.A.A.I. | C2: SEZ. C.A.A.I. | D2: 9200001 | E2: EXTRA REGIONE | F2: MI | H2: Via E. Petrella 19, 20124 Milano (MI)
A3: 9101001 | B3: GRUPPO OCCIDENTALE C.A.A.I. | C3: SEZ. C.A.A.I. | D3: 9200001 | E3: EXTRA REGIONE | F3: TO | H3: Via Barbaroux 1, 10122 Torino (TO)
A4: 9101003 | B4: GRUPPO ORIENTALE C.A.A.I. | C4: SEZ. C.A.A.I. | D4: 9200001 | E4: EXTRA REGIONE | F4: BZ | H4: Via A. Diaz C/O ROBERTO ROSSIN 35/A, 39100 Bolzano (BZ)
A5: 9102007 | B5: AGAI COLL. ABRUZZO | C5: ASSOC.GUIDE ALPINE ITAL. | D5: 9200002 | E5: EXTRA REGIONE | F5: AQ | H5: Via Silvio Pellico – MAP1 – int B/2 c/o Cittadini Agostino, 67010 PRETURO (AQ)
A6: 9102005 | B6: AGAI COLL. ALTO ADIGE | C6: ASSOC.GUIDE ALPINE ITAL. | D6: 9200002 | E6: EXTRA REGIONE | F6: BZ | H6: Piazza Fiera 1, 39100 BOLZANO (BZ)
A7: 9102013 | B7: AGAI COLL. CAMPANIA | C7: ASSOC.GUIDE ALPINE ITAL. | D7: 9200002 | E7: EXTRA REGIONE | F7: NA | H7: Via S. Vito 151, 80056 ERCOLANO (NA)
A8: 9102011 | B8: AGAI COLL. EMILIA | C8: ASSOC.GUIDE ALPINE ITAL. | D8: 9200002 | E8: EXTRA REGIONE | F8: RE | H8: VIA DEI MILLE C/o Sez. CAI Reggio Emilia 32, 42122 REGGIO EMILIA (RE)
A9: 9102012 | B9: AGAI COLL. FRIULI V. G. | C9: ASSOC.GUIDE ALPINE ITAL. | D9: 9200002 | E9: EXTRA REGIONE | F9: TS | H9: Via Grignano 7, 34151 TRIESTE (TS)
A10: 9102014 | B10: AGAI COLL. LIGURIA | C10: ASSOC.GUIDE ALPINE ITAL. | D10: 9200002 | E10: EXTRA REGIONE | F10: SV | H10: Via Pertica c/o Sede Comunale 29, 17024 FINALE LIGURE (SV)
A11: 9102003 | B11: AGAI COLL. LOMBARDIA | C11: ASSOC.GUIDE ALPINE ITAL. | D11: 9200002 | E11: EXTRA REGIONE | F11: SO | H11: Via De Capitani Masegra 5, 23100 SONDRIO (SO)
A12: 9102009 | B12: AGAI COLL. MARCHE | C12: ASSOC.GUIDE ALPINE ITAL. | D12: 9200002 | E12: EXTRA REGIONE | F12: AP | H12: C.da Fonte Balzana C/O VALLESI MARCO 1, 63026 LAPEDONA (AP)
A13: 9102001 | B13: AGAI COLL. PIEMONTE | C13: ASSOC.GUIDE ALPINE ITAL. | D13: 9200002 | E13: EXTRA REGIONE | F13: TO | G13: segreteria@guidealpinepiemonte.it | H13: Via Palazzo di Città C/o Palazzo Municipale 39, 10059 SUSA (TO)
A14: 9102008 | B14: AGAI COLL. SICILIA | C14: ASSOC.GUIDE ALPINE ITAL. | D14: 9200002 | E14: EXTRA REGIONE | F14: CT | H14: Piazza Vittorio Emanuele 43, 95030 NICOLOSI (CT)
A15: 9102010 | B15: AGAI COLL. TOSCANA | C15: ASSOC.GUIDE ALPINE ITAL. | D15: 9200002 | E15: EXTRA REGIONE | F15: PO | H15: Via Giovanni Bacci c/o Cristiano Virgilio 15, 59100 PRATO (PO)
A16: 9102004 | B16: AGAI COLL. TRENTINO | C16: ASSOC.GUIDE ALPINE ITAL. | D16: 9200002 | E16: EXTRA REGIONE | F16: TN | H16: Vicolo Galasso 19, 38100 TRENTO (TN)
A17: 9102002 | B17: AGAI COLL. VALLE D'AOSTA | C17: ASSOC.GUIDE ALPINE ITAL. | D17: 9200002 | E17: EXTRA REGIONE | F17: AO | H17: Via Monte Emilius 13, 11100 AOSTA (AO)
A18: 9102006 | B18: AGAI COLL. VENETO | C18: ASSOC.GUIDE ALPINE ITAL. | D18: 9200002 | E18: EXTRA REGIONE | F18: BL | H18: Corso Italia 69/A, 32043 CORTINA D’AMPEZZO (BL)
A19: 9110001 | B19: S.SEZ. ARENZANO | C19: SEZ. LIGURE-GENOVA | D19: 9210001 | E19: LIGURIA | F19: GE | G19: cai-arenzano@libero.it | H19: Via Cesare Battisti 3, 16011 Arenzano (GE)
A20: 9110003 | B20: S.SEZ. CORNIGLIANO | C20: SEZ. LIGURE-GENOVA | D20: 9210001 | E20: LIGURIA | F20: GE | G20: cornigliano@cailiguregenova.it | H20: Via Nino Cervetto 40 R, 16152 Genova (GE)
A21: 9110009 | B21: S.SEZ. SORI | C21: SEZ. LIGURE-GENOVA | D21: 9210001 | E21: LIGURIA | F21: GE | G21: sabinastella@stellaeassociati.it | H21: Via Stagno 19, 16031 Sori (GE)
A22: 9110006 | B22: S.SEZ. CENGIO | C22: SEZ. SAVONA | D22: 9210003 | E22: LIGURIA | F22: SV | G22: cai.cengio@libero.it | H22: PIAZZA DELLE SCUOLE 4, 17056 CENGIO GENEPRO (SV)
A23: 9110007 | B23: S.SEZ. VALBORMIDA | C23: SEZ. SAVONA | D23: 9210003 | E23: LIGURIA | F23: SV | G23: cai.valbormida@gmail.com | H23: VIA ROMA (PORTA SOPRANA) 1, 17014 CAIRO MONTENOTTE (SV)
A24: 9110004 | B24: S.SEZ. VAL DI VARA-RIVIERA | C24: SEZ. LA SPEZIA | D24: 9210004 | E24: LIGURIA | F24: SP | H24: Centro Polifunzionale C/O COMUNE DI BRUGNATO, 19020 Brugnato (SP)
A25: 9110008 | B25: S.SEZ. GE-SESTRI (diventata Sezione) | C25: SEZ. U.L.E. GENOVA | D25: 9210005 | E25: LIGURIA | F25: GE | H25: Via Galliano 16/4, 16153 Sestri Ponente (GE)
A26: 9112046 | B26: S.SEZ. C.R.A.L. C.R.T. | C26: SEZ. TORINO | D26: 9212001 | E26: PIEMONTE | F26: TO | H26: Via Nizza 150, 10126 Torino (TO)
A27: 9112020 | B27: S.SEZ. G.E.A.T. | C27: SEZ. TORINO | D27: 9212001 | E27: PIEMONTE | F27: TO | H27: Via Barbaroux 1, 10122 Torino (TO)
A28: 9112023 | B28: S.SEZ. S.U.C.A.I. | C28: SEZ. TORINO | D28: 9212001 | E28: PIEMONTE | F28: TO | H28: Via Barbaroux 1, 10131 Torino (TO)
A29: 9112037 | B29: S.SEZ. SANTENA | C29: SEZ. TORINO | D29: 9212001 | E29: PIEMONTE | F29: TO | H29: Vicolo San Lorenzo 27, 10026 Santena (TO)
A30: 9112022 | B30: S.SEZ. SETTIMO TORINESE | C30: SEZ. TORINO | D30: 9212001 | E30: PIEMONTE | F30: TO | H30: Via Buonarroti C/O Unitre 8/C, 10036 Settimo Torinese (TO)
A31: 9112024 | B31: S.SEZ. U.E.T. | C31: SEZ. TORINO | D31: 9212001 | E31: PIEMONTE | F31: TO | H31: Via Maresciallo Giardino C/O CAI SEDE ESTIVA 48, 10131 Torino (TO)
A32: 9112025 | B32: S.SEZ. ALAGNA | C32: SEZ. VARALLO SESIA | D32: 9212002 | E32: PIEMONTE | F32: VC | G32: alagna@caivarallo.it | H32: VIA CENTRO 1, 13021 ALAGNA VALSESIA (VC)
A33: 9112026 | B33: S.SEZ. BORGOSESIA | C33: SEZ. VARALLO SESIA | D33: 9212002 | E33: PIEMONTE | F33: VC | G33: borgosesia@caivarallo.it | H33: Piazza Mazzini (Palazzo Castellani), 13011 Borgosesia (VC)
A34: 9112027 | B34: S.SEZ. GHEMME | C34: SEZ. VARALLO SESIA | D34: 9212002 | E34: PIEMONTE | F34: NO | G34: ghemme@caivarallo.it | H34: Piazza Castello 23, 28074 Ghemme (NO)
A35: 9112028 | B35: S.SEZ. GRIGNASCO | C35: SEZ. VARALLO SESIA | D35: 9212002 | E35: PIEMONTE | F35: NO | G35: grignasco@caivarallo.it | H35: Via Costantino Perazzi 10, 28075 Grignasco (NO)
A36: 9112029 | B36: S.SEZ. ROMAGNANO | C36: SEZ. VARALLO SESIA | D36: 9212002 | E36: PIEMONTE | F36: NO | G36: romagnano@caivarallo.it | H36: Via Fontana del Frate 8, 28078 Romagnano Sesia (NO)
A37: 9112030 | B37: S.SEZ. SCOPELLO | C37: SEZ. VARALLO SESIA | D37: 9212002 | E37: PIEMONTE | F37: VC | G37: scopello@caivarallo.it | H37: c/o Municipio di Scopello, 13020 SCOPELLO (VC)
A38: 9112040 | B38: S.SEZ. BORGO SAN DALMAZZO | C38: SEZ. CUNEO | D38: 9212006 | E38: PIEMONTE | F38: CN | H38: Via Monsignor Riberi 12, 12011 Borgo San Dalmazzo (CN)
A39: 9112010 | B39: S.SEZ. BUSCA | C39: SEZ. CUNEO | D39: 9212006 | E39: PIEMONTE | F39: CN | H39: Via Pes di Villamarina 5, 12022 Busca (CN)
A40: 9112012 | B40: S.SEZ. DRONERO | C40: SEZ. CUNEO | D40: 9212006 | E40: PIEMONTE | F40: CN | H40: Via Pasubio 5, 12025 Dronero (CN)
...

Sheet GR
A1: Nome | B1: Ente del Terzo Settore
A2: CAI GR Abruzzo | B2: Interessato
A3: CAI GR Alto Adige | B3: ETS
A4: CAI GR Basilicata | B4: Non ETS | C4: no risposta
A5: CAI GR Calabria | B5: In fase di iscrizione
A6: CAI GR Campania | B6: In fase di iscrizione
A7: CAI GR Emilia Romagna | B7: ETS
A8: CAI GR Friuli Venezia Giulia | B8: Non ETS
A9: CAI GR Lazio | B9: Non ETS | C9: al momento non interessati ma la questione è ancora in discussione
A10: CAI GR Liguria | B10: ETS
A11: CAI GR Lombardia | B11: Interessato
A12: CAI GR Marche | B12: Interessato | C12: no risposta
A13: CAI GR Molise | B13: Non ETS | C13: no risposta
A14: CAI GR Piemonte | B14: ETS
A15: CAI GR Puglia | B15: In fase di iscrizione | C15: hanno lo statuto bloccato
A16: CAI GR Sardegna | B16: Non ETS | C16: no risposta
A17: CAI GR Sicilia | B17: ETS
A18: CAI GR Toscana | B18: ETS
A19: CAI GR Trentino - SAT | B19: ETS
A20: CAI GR Umbria | B20: Non ETS | C20: non è una loro priorità ma non escludono ancora del tutto
A21: CAI GR Valle D'Aosta | B21: Non ETS
A22: CAI GR Veneto | B22: In fase di iscrizione

Sheet Statistiche Sezioni
B3: Sezioni ETS | C3: %
A4: APS - ETS | B4: =COUNTIF(Sezioni!$P:$P,A4) -> 188 | C4: =B4/B9 -> 0.77366255
A5: ODV - ETS | B5: =COUNTIF(Sezioni!$P:$P,A5) -> 15 | C5: =B5/B9 -> 0.061728395
A6: ETS | B6: =COUNTIF(Sezioni!$P:$P,A6) -> 12 | C6: =B6/B9 -> 0.049382716
A7: Avviata procedura di iscrizione | B7: =COUNTIF(Sezioni!$P:$P,A7) -> 29 | C7: =B7/B9 -> 0.11934156
A9: Sezioni ETS | B9: 243 | C9: =B9/B10 -> 0.46285714
A10: Tootale Sezioni | B10: =525 -> 525
A12: RIEPILOGO PER GR
B13: Sezioni ETS | C13: TOT SEZIONI | D13: % ETS
A14: Abruzzo | B14: =COUNTIFS(Sezioni!$C:$C,A14,Sezioni!$P:$P,"<>") -> 5 | C14: =COUNTIF(Sezioni!$C:$C,A14) -> 24 | D14: =B14/C14 -> 0.20833333
A15: Alto Adige | B15: =COUNTIFS(Sezioni!$C:$C,A15,Sezioni!$P:$P,"<>") -> 12 | C15: =COUNTIF(Sezioni!$C:$C,A15) -> 14 | D15: =B15/C15 -> 0.85714286
A16: Basilicata | B16: =COUNTIFS(Sezioni!$C:$C,A16,Sezioni!$P:$P,"<>") -> 4 | C16: =COUNTIF(Sezioni!$C:$C,A16) -> 4 | D16: =B16/C16 -> 1
A17: Calabria | B17: =COUNTIFS(Sezioni!$C:$C,A17,Sezioni!$P:$P,"<>") -> 5 | C17: =COUNTIF(Sezioni!$C:$C,A17) -> 5 | D17: =B17/C17 -> 1
A18: Campania | B18: =COUNTIFS(Sezioni!$C:$C,A18,Sezioni!$P:$P,"<>") -> 5 | C18: =COUNTIF(Sezioni!$C:$C,A18) -> 9 | D18: =B18/C18 -> 0.55555556
A19: Emilia-Romagna | B19: =COUNTIFS(Sezioni!$C:$C,A19,Sezioni!$P:$P,"<>") -> 20 | C19: =COUNTIF(Sezioni!$C:$C,A19) -> 20 | D19: =B19/C19 -> 1
A20: Friuli-Venezia Giulia | B20: =COUNTIFS(Sezioni!$C:$C,A20,Sezioni!$P:$P,"<>") -> 13 | C20: =COUNTIF(Sezioni!$C:$C,A20) -> 27 | D20: =B20/C20 -> 0.48148148
A21: Lazio | B21: =COUNTIFS(Sezioni!$C:$C,A21,Sezioni!$P:$P,"<>") -> 9 | C21: =COUNTIF(Sezioni!$C:$C,A21) -> 19 | D21: =B21/C21 -> 0.47368421
A22: Liguria | B22: =COUNTIFS(Sezioni!$C:$C,A22,Sezioni!$P:$P,"<>") -> 6 | C22: =COUNTIF(Sezioni!$C:$C,A22) -> 19 | D22: =B22/C22 -> 0.31578947
A23: Lombardia | B23: =COUNTIFS(Sezioni!$C:$C,A23,Sezioni!$P:$P,"<>") -> 49 | C23: =COUNTIF(Sezioni!$C:$C,A23) -> 152 | D23: =B23/C23 -> 0.32236842
A24: Marche | B24: =COUNTIFS(Sezioni!$C:$C,A24,Sezioni!$P:$P,"<>") -> 5 | C24: =COUNTIF(Sezioni!$C:$C,A24) -> 15 | D24: =B24/C24 -> 0.33333333
A25: Molise | B25: =COUNTIFS(Sezioni!$C:$C,A25,Sezioni!$P:$P,"<>") -> 1 | C25: =COUNTIF(Sezioni!$C:$C,A25) -> 2 | D25: =B25/C25 -> 0.5
... A34: Veneto | B34: =COUNTIFS(Sezioni!$C:$C,A34,Sezioni!$P:$P,"<>") -> 36 | C34: =COUNTIF(Sezioni!$C:$C,A34) -> 65 | D34: =B34/C34 -> 0.55384615
B36: =SUM(B14:B34) -> 244 | C36: =SUM(C14:C34) -> 525 | D36: =B36/C36 -> 0.4647619
A39: GRUPPI REGIONALI | B39: GR ETS | C39: %
A40: ETS | B40: =COUNTIF(GR!$B:$B,A40) -> 7 | C40: =B40/B45 -> 0.33333333
A41: In fase di iscrizione | B41: =COUNTIF(GR!$B:$B,A41) -> 4 | C41: =B41/B45 -> 0.19047619
A42: Interessato | B42: =COUNTIF(GR!$B:$B,A42) -> 3 | C42: =B42/B45 -> 0.14285714
A43: NON ETS | B43: =COUNTIF(GR!$B:$B,A43) -> 7 | C43: =B43/B45 -> 0.33333333
B45: =SUM(B40:B43) -> 21
